============================= test session starts ==============================
platform linux -- Python 3.10.12, pytest-7.4.0, pluggy-1.0.0
rootdir: /home/user/anaconda3/envs/Web_scraping/test
collected 0 items / 1 error

==================================== ERRORS ====================================
___________________________ ERROR collecting test.py ___________________________
../lib/python3.10/site-packages/selenium/webdriver/common/driver_finder.py:38: in get_path
    path = SeleniumManager().driver_location(options) if path is None else path
../lib/python3.10/site-packages/selenium/webdriver/common/selenium_manager.py:73: in driver_location
    args = [str(self.get_binary()), "--browser", browser]
../lib/python3.10/site-packages/selenium/webdriver/common/selenium_manager.py:57: in get_binary
    raise WebDriverException(f"Unable to obtain working Selenium Manager binary; {path}")
E   selenium.common.exceptions.WebDriverException: Message: Unable to obtain working Selenium Manager binary; /home/user/anaconda3/envs/Web_scraping/lib/python3.10/site-packages/selenium/webdriver/common/linux/selenium-manager

The above exception was the direct cause of the following exception:
../lib/python3.10/site-packages/_pytest/runner.py:341: in from_call
    result: Optional[TResult] = func()
../lib/python3.10/site-packages/_pytest/runner.py:372: in <lambda>
    call = CallInfo.from_call(lambda: list(collector.collect()), "collect")
../lib/python3.10/site-packages/_pytest/python.py:531: in collect
    self._inject_setup_module_fixture()
../lib/python3.10/site-packages/_pytest/python.py:545: in _inject_setup_module_fixture
    self.obj, ("setUpModule", "setup_module")
../lib/python3.10/site-packages/_pytest/python.py:310: in obj
    self._obj = obj = self._getobj()
../lib/python3.10/site-packages/_pytest/python.py:528: in _getobj
    return self._importtestmodule()
../lib/python3.10/site-packages/_pytest/python.py:617: in _importtestmodule
    mod = import_path(self.path, mode=importmode, root=self.config.rootpath)
../lib/python3.10/site-packages/_pytest/pathlib.py:565: in import_path
    importlib.import_module(module_name)
../lib/python3.10/importlib/__init__.py:126: in import_module
    return _bootstrap._gcd_import(name[level:], package, level)
<frozen importlib._bootstrap>:1050: in _gcd_import
    ???
<frozen importlib._bootstrap>:1027: in _find_and_load
    ???
<frozen importlib._bootstrap>:1006: in _find_and_load_unlocked
    ???
<frozen importlib._bootstrap>:688: in _load_unlocked
    ???
../lib/python3.10/site-packages/_pytest/assertion/rewrite.py:178: in exec_module
    exec(co, module.__dict__)
test.py:8: in <module>
    driver = webdriver.Chrome()
../lib/python3.10/site-packages/selenium/webdriver/chrome/webdriver.py:45: in __init__
    super().__init__(
../lib/python3.10/site-packages/selenium/webdriver/chromium/webdriver.py:51: in __init__
    self.service.path = DriverFinder.get_path(self.service, options)
../lib/python3.10/site-packages/selenium/webdriver/common/driver_finder.py:41: in get_path
    raise NoSuchDriverException(msg) from err
E   selenium.common.exceptions.NoSuchDriverException: Message: Unable to obtain driver for chrome using Selenium Manager.; For documentation on this error, please visit: https://www.selenium.dev/documentation/webdriver/troubleshooting/errors/driver_location
=========================== short test summary info ============================
ERROR test.py - selenium.common.exceptions.NoSuchDriverException: Message: Un...
!!!!!!!!!!!!!!!!!!!! Interrupted: 1 error during collection !!!!!!!!!!!!!!!!!!!!
=============================== 1 error in 0.53s ===============================
